<?xml version="1.0" ?>
<robot name="simple_sliders">
  

  <material name="Grey">
    
    
    <color rgba="0.2 0.2 0.2 1.0"/>
    
  
  </material>
  
  
  <material name="Orange">
    
    
    <color rgba="1.0 0.423529411765 0.0392156862745 1.0"/>
    
  
  </material>
  
  
  <material name="Blue">
    
    
    <color rgba="0.5 0.7 1.0 1.0"/>
          
  
  </material>
  



  
  <link name="base_link">
  </link>
  
  
  
  
  <joint name="x_axis" type="prismatic">
    
    
    <parent link="base_link"/>
    
    
    <child link="link_2d_plane"/>
    
    
    <origin rpy="0 0 0" xyz="0 0 0"/>
    
    
    <axis xyz="1.0 0 0"/>
    
    
    <limit lower="-4" upper="4" effort="0" velocity="0"/>
    
    
    <dynamics damping="0.5"/>
    
  
  </joint>
  
  
  
  <link name="link_2d_plane">
  </link>
  
  
  
  
  <joint name="y_axis" type="prismatic">
    
    
    <parent link="link_2d_plane"/>
    
    
    <child link="lbr_iiwa_link_0"/>
    
    
    <origin rpy="0 0 0" xyz="0 0 0"/>
    
    
    <axis xyz="0 1.0 0"/>
    
    
    <limit lower="-4" upper="4" effort="0" velocity="0"/>
    
    
    <dynamics damping="0.5"/>
    
  
  </joint>
  

  
  
  
  
  
  
  
  
  
  <link name="lbr_iiwa_link_0">
    
    
    <inertial>
      
      
      <origin rpy="0 0 0" xyz="-0.1 0 0.07"/>
      
      
      
      <mass value="0.0"/>
      
      
      <inertia ixx="0.05" ixy="0" ixz="0" iyy="0.06" iyz="0" izz="0.03"/>
      
    
    </inertial>
    
    
    <visual>
      
      
      <origin rpy="0 0 0" xyz="0 0 0"/>
      
      
      <geometry>
        
        
        <mesh filename="meshes/link_0.obj"/>
        
      
      </geometry>
      
      
      <material name="Grey"/>
      
    
    </visual>
    
    
    <collision>
      
      
      <origin rpy="0 0 0" xyz="0 0 0"/>
      
      
      <geometry>
        
        
        <mesh filename="meshes/link_0.stl"/>
        
      
      </geometry>
      
    
    </collision>
    
  
  </link>
  
  
  
  <joint name="lbr_iiwa_joint_1" type="revolute">
    
    
    <parent link="lbr_iiwa_link_0"/>
    
    
    <child link="lbr_iiwa_link_1"/>
    
    
    <origin rpy="0 0 0" xyz="0 0 0.1575"/>
    
    
    <axis xyz="0 0 1"/>
    
    
    <limit effort="300" lower="-2.96705972839" upper="2.96705972839" velocity="10"/>
    
    
    <dynamics damping="0.5"/>
    
  
  </joint>
  
  
  <link name="lbr_iiwa_link_1">
    
    
    <inertial>
      
      
      <origin rpy="0 0 0" xyz="0 -0.03 0.12"/>
      
      
      <mass value="4"/>
      
      
      <inertia ixx="0.1" ixy="0" ixz="0" iyy="0.09" iyz="0" izz="0.02"/>
      
    
    </inertial>
    
    
    <visual>
      
      
      <origin rpy="0 0 0" xyz="0 0 0"/>
      
      
      <geometry>
        
        
        <mesh filename="meshes/link_1.obj"/>
        
      
      </geometry>
      
      
      <material name="Blue"/>
      
    
    </visual>
    
    
    <collision>
      
      
      <origin rpy="0 0 0" xyz="0 0 0"/>
      
      
      <geometry>
        
        
        <mesh filename="meshes/link_1.stl"/>
        
      
      </geometry>
      
    
    </collision>
    
  
  </link>
  
  
  
  <joint name="lbr_iiwa_joint_2" type="revolute">
    
    
    <parent link="lbr_iiwa_link_1"/>
    
    
    <child link="lbr_iiwa_link_2"/>
    
    
    <origin rpy="1.57079632679   0 3.14159265359" xyz="0 0 0.2025"/>
    
    
    <axis xyz="0 0 1"/>
    
    
    <limit effort="300" lower="-2.09439510239" upper="2.09439510239" velocity="10"/>
    
    
    <dynamics damping="0.5"/>
    
  
  </joint>
  
  
  <link name="lbr_iiwa_link_2">
    
    
    <inertial>
      
      
      <origin rpy="0 0 0" xyz="0.0003 0.059 0.042"/>
      
      
      <mass value="4"/>
      
      
      <inertia ixx="0.05" ixy="0" ixz="0" iyy="0.018" iyz="0" izz="0.044"/>
      
    
    </inertial>
    
    
    <visual>
      
      
      <origin rpy="0 0 0" xyz="0 0 0"/>
      
      
      <geometry>
        
        
        <mesh filename="meshes/link_2.obj"/>
        
      
      </geometry>
      
      
      <material name="Blue"/>
      
    
    </visual>
    
    
    <collision>
      
      
      <origin rpy="0 0 0" xyz="0 0 0"/>
      
      
      <geometry>
        
        
        <mesh filename="meshes/link_2.stl"/>
        
      
      </geometry>
      
    
    </collision>
    
  
  </link>
  
  
  
  <joint name="lbr_iiwa_joint_3" type="revolute">
    
    
    <parent link="lbr_iiwa_link_2"/>
    
    
    <child link="lbr_iiwa_link_3"/>
    
    
    <origin rpy="1.57079632679 0 3.14159265359" xyz="0 0.2045 0"/>
    
    
    <axis xyz="0 0 1"/>
    
    
    <limit effort="300" lower="-2.96705972839" upper="2.96705972839" velocity="10"/>
    
    
    <dynamics damping="0.5"/>
    
  
  </joint>
  
  
  <link name="lbr_iiwa_link_3">
    
    
    <inertial>
      
      
      <origin rpy="0 0 0" xyz="0 0.03 0.13"/>
      
      
      <mass value="3"/>
      
      
      <inertia ixx="0.08" ixy="0" ixz="0" iyy="0.075" iyz="0" izz="0.01"/>
      
    
    </inertial>
    
    
    <visual>
      
      
      <origin rpy="0 0 0" xyz="0 0 0"/>
      
      
      <geometry>
        
        
        <mesh filename="meshes/link_3.obj"/>
        
      
      </geometry>
      
      
      <material name="Orange"/>
      
    
    </visual>
    
    
    <collision>
      
      
      <origin rpy="0 0 0" xyz="0 0 0"/>
      
      
      <geometry>
        
        
        <mesh filename="meshes/link_3.stl"/>
        
      
      </geometry>
      
    
    </collision>
    
  
  </link>
  
  
  
  <joint name="lbr_iiwa_joint_4" type="revolute">
    
    
    <parent link="lbr_iiwa_link_3"/>
    
    
    <child link="lbr_iiwa_link_4"/>
    
    
    <origin rpy="1.57079632679 0 0" xyz="0 0 0.2155"/>
    
    
    <axis xyz="0 0 1"/>
    
    
    <limit effort="300" lower="-2.09439510239" upper="2.09439510239" velocity="10"/>
    
    
    <dynamics damping="0.5"/>
    
  
  </joint>
  
  
  <link name="lbr_iiwa_link_4">
    
    
    <inertial>
      
      
      <origin rpy="0 0 0" xyz="0 0.067 0.034"/>
      
      
      <mass value="2.7"/>
      
      
      <inertia ixx="0.03" ixy="0" ixz="0" iyy="0.01" iyz="0" izz="0.029"/>
      
    
    </inertial>
    
    
    <visual>
      
      
      <origin rpy="0 0 0" xyz="0 0 0"/>
      
      
      <geometry>
        
        
        <mesh filename="meshes/link_4.obj"/>
        
      
      </geometry>
      
      
      <material name="Blue"/>
      
    
    </visual>
    
    
    <collision>
      
      
      <origin rpy="0 0 0" xyz="0 0 0"/>
      
      
      <geometry>
        
        
        <mesh filename="meshes/link_4.stl"/>
        
      
      </geometry>
      
    
    </collision>
    
  
  </link>
  
  
  
  <joint name="lbr_iiwa_joint_5" type="revolute">
    
    
    <parent link="lbr_iiwa_link_4"/>
    
    
    <child link="lbr_iiwa_link_5"/>
    
    
    <origin rpy="-1.57079632679 3.14159265359 0" xyz="0 0.1845 0"/>
    
    
    <axis xyz="0 0 1"/>
    
    
    <limit effort="300" lower="-2.96705972839" upper="2.96705972839" velocity="10"/>
    
    
    <dynamics damping="0.5"/>
    
  
  </joint>
  
  
  <link name="lbr_iiwa_link_5">
    
    
    <inertial>
      
      
      <origin rpy="0 0 0" xyz="0.0001 0.021 0.076"/>
      
      
      <mass value="1.7"/>
      
      
      <inertia ixx="0.02" ixy="0" ixz="0" iyy="0.018" iyz="0" izz="0.005"/>
      
    
    </inertial>
    
    
    <visual>
      
      
      <origin rpy="0 0 0" xyz="0 0 0"/>
      
      
      <geometry>
        
        
        <mesh filename="meshes/link_5.obj"/>
        
      
      </geometry>
      
      
      <material name="Blue"/>
      
    
    </visual>
    
    
    <collision>
      
      
      <origin rpy="0 0 0" xyz="0 0 0"/>
      
      
      <geometry>
        
        
        <mesh filename="meshes/link_5.stl"/>
        
      
      </geometry>
      
    
    </collision>
    
  
  </link>
  
  
  
  <joint name="lbr_iiwa_joint_6" type="revolute">
    
    
    <parent link="lbr_iiwa_link_5"/>
    
    
    <child link="lbr_iiwa_link_6"/>
    
    
    <origin rpy="1.57079632679 0 0" xyz="0 0 0.2155"/>
    
    
    <axis xyz="0 0 1"/>
    
    
    <limit effort="300" lower="-2.09439510239" upper="2.09439510239" velocity="10"/>
    
    
    <dynamics damping="0.5"/>
    
  
  </joint>
  
  
  <link name="lbr_iiwa_link_6">
    
    
    <inertial>
      
      
      <origin rpy="0 0 0" xyz="0 0.0006 0.0004"/>
      
      
      <mass value="1.8"/>
      
      
      <inertia ixx="0.005" ixy="0" ixz="0" iyy="0.0036" iyz="0" izz="0.0047"/>
      
    
    </inertial>
    
    
    <visual>
      
      
      <origin rpy="0 0 0" xyz="0 0 0"/>
      
      
      <geometry>
        
        
        <mesh filename="meshes/link_6.obj"/>
        
      
      </geometry>
      
      
      <material name="Orange"/>
      
    
    </visual>
    
    
    <collision>
      
      
      <origin rpy="0 0 0" xyz="0 0 0"/>
      
      
      <geometry>
        
        
        <mesh filename="meshes/link_6.stl"/>
        
      
      </geometry>
      
    
    </collision>
    
  
  </link>
  
  
  
  <joint name="lbr_iiwa_joint_7" type="revolute">
    
    
    <parent link="lbr_iiwa_link_6"/>
    
    
    <child link="lbr_iiwa_link_7"/>
    
    
    <origin rpy="-1.57079632679 3.14159265359 0" xyz="0 0.081 0"/>
    
    
    <axis xyz="0 0 1"/>
    
    
    <limit effort="300" lower="-3.05432619099" upper="3.05432619099" velocity="10"/>
    
    
    <dynamics damping="0.5"/>
    
  
  </joint>
  
  
  <link name="lbr_iiwa_link_7">
    
    
    <inertial>
      
      
      <origin rpy="0 0 0" xyz="0 0 0.02"/>
      
      
      <mass value="0.3"/>
      
      
      <inertia ixx="0.001" ixy="0" ixz="0" iyy="0.001" iyz="0" izz="0.001"/>
      
    
    </inertial>
    
    
    <visual>
      
      
      <origin rpy="0 0 0" xyz="0 0 0"/>
      
      
      <geometry>
        
        
        <mesh filename="meshes/link_7.obj"/>
        
      
      </geometry>
      
      
      <material name="Grey"/>
      
    
    </visual>
    
    
    <collision>
      
      
      <origin rpy="0 0 0" xyz="0 0 0"/>
      
      
      <geometry>
        
        
        <mesh filename="meshes/link_7.stl"/>
        
      
      </geometry>
      
    
    </collision>
    
  
  </link>
  
  

  <link name="goal">
    
      
    <visual name="visual_box_0_link_0.001">
      
        
      <origin xyz="0 0 0" rpy="0 0 0"/>
      
        
      <geometry>
        
          
        <box size="0.79103 0.09453 0.09453"/>
        
        
      </geometry>
      
        
      <material name="green_translucent"/>
      
      
    </visual>
    
    
  </link>
  

    
  <link name="link_0_joint_0">
    
      
    <visual name="visual_box_0_link_0">
      
        
      <origin xyz="0 0 0" rpy="0 0 0"/>
      
        
      <geometry>
        
          
        <box size="0.795 0.095 0.095"/>
        
        
      </geometry>
      
        
      <material name="green"/>
      
      
    </visual>
    
      
    <collision name="collision_box_0_link_0">
      
        
      <origin xyz="0 0 0" rpy="0 0 0"/>
      
        
      <geometry>
        
          
        <box size="0.795 0.095 0.095"/>
        
        
      </geometry>
      
      
    </collision>
    
    
  </link>
  

    
  <link name="link_1_joint_0">
    
      
    <visual name="visual_box_3_link_1">
      
        
      <origin xyz="0 0 0" rpy="0 0 0"/>
      
        
      <geometry>
        
          
        <box size="0.795 0.095 0.095"/>
        
        
      </geometry>
      
        
      <material name="red"/>
      
      
    </visual>
    
      
    <collision name="collision_box_3_link_1">
      
        
      <origin xyz="0 0 0" rpy="0 0 0"/>
      
        
      <geometry>
        
          
        <box size="0.795 0.095 0.095"/>
        
        
      </geometry>
      
      
    </collision>
    
    
  </link>
  

    
  <link name="link_2_joint_0">
    
      
    <visual name="visual_box_6_link_2">
      
        
      <origin xyz="0 0 0" rpy="0 0 0"/>
      
        
      <geometry>
        
          
        <box size="0.795 0.095 0.095"/>
        
        
      </geometry>
      
        
      <material name="red"/>
      
      
    </visual>
    
      
    <collision name="collision_box_6_link_2">
      
        
      <origin xyz="0 0 0" rpy="0 0 0"/>
      
        
      <geometry>
        
          
        <box size="0.795 0.095 0.095"/>
        
        
      </geometry>
      
      
    </collision>
    
    
  </link>
  

    
  <link name="link_3_joint_0">
    
      
    <visual name="visual_box_9_link_3">
      
        
      <origin xyz="0 0 0" rpy="0 0 0"/>
      
        
      <geometry>
        
          
        <box size="0.795 0.095 0.095"/>
        
        
      </geometry>
      
        
      <material name="red"/>
      
      
    </visual>
    
      
    <collision name="collision_box_9_link_3">
      
        
      <origin xyz="0 0 0" rpy="0 0 0"/>
      
        
      <geometry>
        
          
        <box size="0.795 0.095 0.095"/>
        
        
      </geometry>
      
      
    </collision>
    
    
  </link>
  

    
  <link name="link_fixed_10_handle_shaft">
    
      
    <visual name="visual_box_fixed_10_handle_shaft">
      
        
      <origin xyz="0 0 0" rpy="0 0 0"/>
      
        
      <geometry>
        
          
        <box size="0.095 0.095 0.12"/>
        
        
      </geometry>
      
        
      <material name="red"/>
      
      
    </visual>
    
      
    <collision name="collision_box_fixed_10_handle_shaft">
      
        
      <origin xyz="0 0 0" rpy="0 0 0"/>
      
        
      <geometry>
        
          
        <box size="0.095 0.095 0.12"/>
        
        
      </geometry>
      
      
    </collision>
    
    
  </link>
  

    
  <link name="link_fixed_11_handle_knob">
    
      
    <visual name="visual_box_fixed_11_handle_knob">
      
        
      <origin xyz="0 0 0" rpy="0 0 0"/>
      
        
      <geometry>
        
          
        <box size="0.045 0.045 0.195"/>
        
        
      </geometry>
      
        
      <material name="yellow"/>
      
      
    </visual>
    
      
    <collision name="collision_box_fixed_11_handle_knob">
      
        
      <origin xyz="0 0 0" rpy="0 0 0"/>
      
        
      <geometry>
        
          
        <box size="0.045 0.045 0.195"/>
        
        
      </geometry>
      
      
    </collision>
    
    
  </link>
  

    
  <link name="link_fixed_1_handle_shaft">
    
      
    <visual name="visual_box_fixed_1_handle_shaft">
      
        
      <origin xyz="0 0 0" rpy="0 0 0"/>
      
        
      <geometry>
        
          
        <box size="0.095 0.095 0.12"/>
        
        
      </geometry>
      
        
      <material name="green"/>
      
      
    </visual>
    
      
    <collision name="collision_box_fixed_1_handle_shaft">
      
        
      <origin xyz="0 0 0" rpy="0 0 0"/>
      
        
      <geometry>
        
          
        <box size="0.095 0.095 0.12"/>
        
        
      </geometry>
      
      
    </collision>
    
    
  </link>
  

    
  <link name="link_fixed_1_handle_shaft.001">
    
      
    <visual name="visual_box_fixed_1_handle_shaft.001">
      
        
      <origin xyz="0 0 0" rpy="0 0 0"/>
      
        
      <geometry>
        
          
        <box size="0.09453 0.09453 0.1194"/>
        
        
      </geometry>
      
        
      <material name="green_translucent"/>
      
      
    </visual>
    
    
  </link>
  

    
  <link name="link_fixed_2_handle_knob">
    
      
    <visual name="visual_box_fixed_2_handle_knob">
      
        
      <origin xyz="0 0 0" rpy="0 0 0"/>
      
        
      <geometry>
        
          
        <box size="0.045 0.045 0.195"/>
        
        
      </geometry>
      
        
      <material name="yellow"/>
      
      
    </visual>
    
      
    <collision name="collision_box_fixed_2_handle_knob">
      
        
      <origin xyz="0 0 0" rpy="0 0 0"/>
      
        
      <geometry>
        
          
        <box size="0.045 0.045 0.195"/>
        
        
      </geometry>
      
      
    </collision>
    
    
  </link>
  

    
  <link name="link_fixed_2_handle_knob.001">
    
      
    <visual name="visual_box_fixed_2_handle_knob.001">
      
        
      <origin xyz="0 0 0" rpy="0 0 0"/>
      
        
      <geometry>
        
          
        <box size="0.04478 0.04478 0.19402"/>
        
        
      </geometry>
      
        
      <material name="green_translucent"/>
      
      
    </visual>
    
    
  </link>
  

    
  <link name="link_fixed_4_handle_shaft">
    
      
    <visual name="visual_box_fixed_4_handle_shaft">
      
        
      <origin xyz="0 0 0" rpy="0 0 0"/>
      
        
      <geometry>
        
          
        <box size="0.095 0.095 0.12"/>
        
        
      </geometry>
      
        
      <material name="red"/>
      
      
    </visual>
    
      
    <collision name="collision_box_fixed_4_handle_shaft">
      
        
      <origin xyz="0 0 0" rpy="0 0 0"/>
      
        
      <geometry>
        
          
        <box size="0.095 0.095 0.12"/>
        
        
      </geometry>
      
      
    </collision>
    
    
  </link>
  

    
  <link name="link_fixed_5_handle_knob">
    
      
    <visual name="visual_box_fixed_5_handle_knob">
      
        
      <origin xyz="0 0 0" rpy="0 0 0"/>
      
        
      <geometry>
        
          
        <box size="0.045 0.045 0.195"/>
        
        
      </geometry>
      
        
      <material name="yellow"/>
      
      
    </visual>
    
      
    <collision name="collision_box_fixed_5_handle_knob">
      
        
      <origin xyz="0 0 0" rpy="0 0 0"/>
      
        
      <geometry>
        
          
        <box size="0.045 0.045 0.195"/>
        
        
      </geometry>
      
      
    </collision>
    
    
  </link>
  

    
  <link name="link_fixed_7_handle_shaft">
    
      
    <visual name="visual_box_fixed_7_handle_shaft">
      
        
      <origin xyz="0 0 0" rpy="0 0 0"/>
      
        
      <geometry>
        
          
        <box size="0.095 0.095 0.12"/>
        
        
      </geometry>
      
        
      <material name="red"/>
      
      
    </visual>
    
      
    <collision name="collision_box_fixed_7_handle_shaft">
      
        
      <origin xyz="0 0 0" rpy="0 0 0"/>
      
        
      <geometry>
        
          
        <box size="0.095 0.095 0.12"/>
        
        
      </geometry>
      
      
    </collision>
    
    
  </link>
  

    
  <link name="link_fixed_8_handle_knob">
    
      
    <visual name="visual_box_fixed_8_handle_knob">
      
        
      <origin xyz="0 0 0" rpy="0 0 0"/>
      
        
      <geometry>
        
          
        <box size="0.045 0.045 0.195"/>
        
        
      </geometry>
      
        
      <material name="yellow"/>
      
      
    </visual>
    
      
    <collision name="collision_box_fixed_8_handle_knob">
      
        
      <origin xyz="0 0 0" rpy="0 0 0"/>
      
        
      <geometry>
        
          
        <box size="0.045 0.045 0.195"/>
        
        
      </geometry>
      
      
    </collision>
    
    
  </link>
  

    
  <joint name="goal" type="fixed">
    
      
    <origin xyz="0 -0.5 0.05" rpy="0 0 -1.5708"/>
    
      
    <parent link="base_link"/>
    
      
    <child link="goal"/>
    
      
    <limit effort="0" velocity="0"/>
    
    
  </joint>
  

    
  <joint name="link_0_joint_0" type="prismatic">
    
      
    <origin xyz="0 0 0.05" rpy="0 0 -1.5708"/>
    
      
    <parent link="base_link"/>
    
      
    <child link="link_0_joint_0"/>
    
      
    <axis xyz="1.0 0 0"/>
    
      
    <limit lower="0" upper="0.5" effort="0" velocity="0"/>
    
    
  </joint>
  

    
  <joint name="link_1_joint_0" type="prismatic">
    
      
    <origin xyz="0 -0.5 0.05" rpy="0 0 0"/>
    
      
    <parent link="base_link"/>
    
      
    <child link="link_1_joint_0"/>
    
      
    <axis xyz="1.0 0 0"/>
    
      
    <limit lower="0" upper="0.5" effort="0" velocity="0"/>
    
    
  </joint>
  

    
  <joint name="link_2_joint_0" type="prismatic">
    
      
    <origin xyz="0.5 -0.5 0.05" rpy="0 0 -1.5708"/>
    
      
    <parent link="base_link"/>
    
      
    <child link="link_2_joint_0"/>
    
      
    <axis xyz="1.0 0 0"/>
    
      
    <limit lower="0" upper="0.5" effort="0" velocity="0"/>
    
    
  </joint>
  

    
  <joint name="link_3_joint_0" type="prismatic">
    
      
    <origin xyz="0.5 -1.0 0.05" rpy="0 0 0"/>
    
      
    <parent link="base_link"/>
    
      
    <child link="link_3_joint_0"/>
    
      
    <axis xyz="1.0 0 0"/>
    
      
    <limit lower="0" upper="0.5" effort="0" velocity="0"/>
    
    
  </joint>
  

    
  <joint name="link_fixed_10_handle_shaft" type="fixed">
    
      
    <origin xyz="0 0 0.1125" rpy="0 0 0"/>
    
      
    <parent link="link_3_joint_0"/>
    
      
    <child link="link_fixed_10_handle_shaft"/>
    
    
  </joint>
  

    
  <joint name="link_fixed_11_handle_knob" type="fixed">
    
      
    <origin xyz="0 0 0.1625" rpy="0 0 0"/>
    
      
    <parent link="link_fixed_10_handle_shaft"/>
    
      
    <child link="link_fixed_11_handle_knob"/>
    
    
  </joint>
  

    
  <joint name="link_fixed_1_handle_shaft" type="fixed">
    
      
    <origin xyz="0 0 0.1125" rpy="0 0 0"/>
    
      
    <parent link="link_0_joint_0"/>
    
      
    <child link="link_fixed_1_handle_shaft"/>
    
    
  </joint>
  

    
  <joint name="link_fixed_1_handle_shaft.001" type="fixed">
    
      
    <origin xyz="0 0 0.11194" rpy="0 0 0"/>
    
      
    <parent link="goal"/>
    
      
    <child link="link_fixed_1_handle_shaft.001"/>
    
    
  </joint>
  

    
  <joint name="link_fixed_2_handle_knob" type="fixed">
    
      
    <origin xyz="0 0 0.1625" rpy="0 0 0"/>
    
      
    <parent link="link_fixed_1_handle_shaft"/>
    
      
    <child link="link_fixed_2_handle_knob"/>
    
    
  </joint>
  

    
  <joint name="link_fixed_2_handle_knob.001" type="fixed">
    
      
    <origin xyz="0 0 0.16169" rpy="0 0 0"/>
    
      
    <parent link="link_fixed_1_handle_shaft.001"/>
    
      
    <child link="link_fixed_2_handle_knob.001"/>
    
    
  </joint>
  

    
  <joint name="link_fixed_4_handle_shaft" type="fixed">
    
      
    <origin xyz="0 0 0.1125" rpy="0 0 0"/>
    
      
    <parent link="link_1_joint_0"/>
    
      
    <child link="link_fixed_4_handle_shaft"/>
    
    
  </joint>
  

    
  <joint name="link_fixed_5_handle_knob" type="fixed">
    
      
    <origin xyz="0 0 0.1625" rpy="0 0 0"/>
    
      
    <parent link="link_fixed_4_handle_shaft"/>
    
      
    <child link="link_fixed_5_handle_knob"/>
    
    
  </joint>
  

    
  <joint name="link_fixed_7_handle_shaft" type="fixed">
    
      
    <origin xyz="0 0 0.1125" rpy="0 0 0"/>
    
      
    <parent link="link_2_joint_0"/>
    
      
    <child link="link_fixed_7_handle_shaft"/>
    
    
  </joint>
  

    
  <joint name="link_fixed_8_handle_knob" type="fixed">
    
      
    <origin xyz="0 0 0.1625" rpy="0 0 0"/>
    
      
    <parent link="link_fixed_7_handle_shaft"/>
    
      
    <child link="link_fixed_8_handle_knob"/>
    
    
  </joint>
  

    
  <material name="green">
    
      
    <color rgba="0 1.0 0 1.0"/>
    
    
  </material>
  

    
  <material name="green_translucent">
    
      
    <color rgba="0 1.0 0 0.25"/>
    
    
  </material>
  

    
  <material name="red">
    
      
    <color rgba="1.0 0 0 1.0"/>
    
    
  </material>
  

    
  <material name="yellow">
    
      
    <color rgba="1.0 1.0 0 1.0"/>
    
    
  </material>
  

  
</robot>
