<?xml version="1.0"?>
<!-- created with Phobos 1.0.1 "Capricious Choutengan" -->
  <robot name="grid_world3">

    <link name="base_link">
    </link>

    <link name="goal">
      <visual name="visual_box_0_link_0.001">
        <origin xyz="0 0 0" rpy="0 0 0"/>
        <geometry>
          <box size="1.8971 0.8981 0.8981"/>
        </geometry>
        <material name="green_translucent"/>
      </visual>
    </link>

    <link name="link_0_joint_0">
      <visual name="visual_box_0_link_0">
        <origin xyz="0 0 0" rpy="0 0 0"/>
        <geometry>
          <box size="1.899 0.899 0.899"/>
        </geometry>
        <material name="green"/>
      </visual>
      <collision name="collision_box_0_link_0">
        <origin xyz="0 0 0" rpy="0 0 0"/>
        <geometry>
          <box size="1.899 0.899 0.899"/>
        </geometry>
      </collision>
    </link>

    <link name="link_1_joint_0">
      <visual name="visual_box_3_link_1">
        <origin xyz="0 0 0" rpy="0 0 0"/>
        <geometry>
          <box size="1.899 0.899 0.899"/>
        </geometry>
        <material name="red"/>
      </visual>
      <collision name="collision_box_3_link_1">
        <origin xyz="0 0 0" rpy="0 0 0"/>
        <geometry>
          <box size="1.899 0.899 0.899"/>
        </geometry>
      </collision>
    </link>

    <link name="link_2_joint_0">
      <visual name="visual_box_6_link_2">
        <origin xyz="0 0 0" rpy="0 0 0"/>
        <geometry>
          <box size="2.899 0.899 0.899"/>
        </geometry>
        <material name="red"/>
      </visual>
      <collision name="collision_box_6_link_2">
        <origin xyz="0 0 0" rpy="0 0 0"/>
        <geometry>
          <box size="2.899 0.899 0.899"/>
        </geometry>
      </collision>
    </link>

    <link name="link_3_joint_0">
      <visual name="visual_box_10_link_3">
        <origin xyz="0 0 0" rpy="0 0 0"/>
        <geometry>
          <box size="2.899 0.899 0.899"/>
        </geometry>
        <material name="red"/>
      </visual>
      <collision name="collision_box_10_link_3">
        <origin xyz="0 0 0" rpy="0 0 0"/>
        <geometry>
          <box size="2.899 0.899 0.899"/>
        </geometry>
      </collision>
    </link>

    <link name="link_4_joint_0">
      <visual name="visual_box_14_link_4">
        <origin xyz="0 0 0" rpy="0 0 0"/>
        <geometry>
          <box size="1.899 0.899 0.899"/>
        </geometry>
        <material name="red"/>
      </visual>
      <collision name="collision_box_14_link_4">
        <origin xyz="0 0 0" rpy="0 0 0"/>
        <geometry>
          <box size="1.899 0.899 0.899"/>
        </geometry>
      </collision>
    </link>

    <link name="link_fixed_11_hinge">
      <visual name="visual_cylinder_fixed_11_hinge">
        <origin xyz="0 0 0" rpy="0 0 0"/>
        <geometry>
          <cylinder radius="0.112" length="0.989"/>
        </geometry>
        <material name="gray"/>
      </visual>
    </link>

    <link name="link_fixed_12_handle_shaft">
      <visual name="visual_cylinder_fixed_12_handle_shaft">
        <origin xyz="0 0 0" rpy="0 0 0"/>
        <geometry>
          <cylinder radius="0.0995" length="0.499"/>
        </geometry>
        <material name="red"/>
      </visual>
      <collision name="collision_cylinder_fixed_12_handle_shaft">
        <origin xyz="0 0 0" rpy="0 0 0"/>
        <geometry>
          <cylinder radius="0.0995" length="0.499"/>
        </geometry>
      </collision>
    </link>

    <link name="link_fixed_13_handle_knob">
      <visual name="visual_box_fixed_13_handle_knob">
        <origin xyz="0 0 0" rpy="0 0 0"/>
        <geometry>
          <box size="0.049 0.049 0.199"/>
        </geometry>
        <material name="yellow"/>
      </visual>
      <collision name="collision_box_fixed_13_handle_knob">
        <origin xyz="0 0 0" rpy="0 0 0"/>
        <geometry>
          <box size="0.049 0.049 0.199"/>
        </geometry>
      </collision>
    </link>

    <link name="link_fixed_15_handle_shaft">
      <visual name="visual_box_fixed_15_handle_shaft">
        <origin xyz="0 0 0" rpy="0 0 0"/>
        <geometry>
          <box size="0.199 0.199 0.499"/>
        </geometry>
        <material name="red"/>
      </visual>
      <collision name="collision_box_fixed_15_handle_shaft">
        <origin xyz="0 0 0" rpy="0 0 0"/>
        <geometry>
          <box size="0.199 0.199 0.499"/>
        </geometry>
      </collision>
    </link>

    <link name="link_fixed_16_handle_knob">
      <visual name="visual_box_fixed_16_handle_knob">
        <origin xyz="0 0 0" rpy="0 0 0"/>
        <geometry>
          <box size="0.049 0.049 0.199"/>
        </geometry>
        <material name="yellow"/>
      </visual>
      <collision name="collision_box_fixed_16_handle_knob">
        <origin xyz="0 0 0" rpy="0 0 0"/>
        <geometry>
          <box size="0.049 0.049 0.199"/>
        </geometry>
      </collision>
    </link>

    <link name="link_fixed_1_handle_shaft">
      <visual name="visual_box_fixed_1_handle_shaft">
        <origin xyz="0 0 0" rpy="0 0 0"/>
        <geometry>
          <box size="0.199 0.199 0.499"/>
        </geometry>
        <material name="green"/>
      </visual>
      <collision name="collision_box_fixed_1_handle_shaft">
        <origin xyz="0 0 0" rpy="0 0 0"/>
        <geometry>
          <box size="0.199 0.199 0.499"/>
        </geometry>
      </collision>
    </link>

    <link name="link_fixed_1_handle_shaft.001">
      <visual name="visual_box_fixed_1_handle_shaft.001">
        <origin xyz="0 0 0" rpy="0 0 0"/>
        <geometry>
          <box size="0.1988 0.1988 0.4985"/>
        </geometry>
        <material name="green_translucent"/>
      </visual>
    </link>

    <link name="link_fixed_2_handle_knob">
      <visual name="visual_box_fixed_2_handle_knob">
        <origin xyz="0 0 0" rpy="0 0 0"/>
        <geometry>
          <box size="0.049 0.049 0.199"/>
        </geometry>
        <material name="yellow"/>
      </visual>
      <collision name="collision_box_fixed_2_handle_knob">
        <origin xyz="0 0 0" rpy="0 0 0"/>
        <geometry>
          <box size="0.049 0.049 0.199"/>
        </geometry>
      </collision>
    </link>

    <link name="link_fixed_2_handle_knob.001">
      <visual name="visual_box_fixed_2_handle_knob.001">
        <origin xyz="0 0 0" rpy="0 0 0"/>
        <geometry>
          <box size="0.04895 0.04895 0.1988"/>
        </geometry>
        <material name="green_translucent"/>
      </visual>
    </link>

    <link name="link_fixed_4_handle_shaft">
      <visual name="visual_box_fixed_4_handle_shaft">
        <origin xyz="0 0 0" rpy="0 0 0"/>
        <geometry>
          <box size="0.199 0.199 0.499"/>
        </geometry>
        <material name="red"/>
      </visual>
      <collision name="collision_box_fixed_4_handle_shaft">
        <origin xyz="0 0 0" rpy="0 0 0"/>
        <geometry>
          <box size="0.199 0.199 0.499"/>
        </geometry>
      </collision>
    </link>

    <link name="link_fixed_5_handle_knob">
      <visual name="visual_box_fixed_5_handle_knob">
        <origin xyz="0 0 0" rpy="0 0 0"/>
        <geometry>
          <box size="0.049 0.049 0.199"/>
        </geometry>
        <material name="yellow"/>
      </visual>
      <collision name="collision_box_fixed_5_handle_knob">
        <origin xyz="0 0 0" rpy="0 0 0"/>
        <geometry>
          <box size="0.049 0.049 0.199"/>
        </geometry>
      </collision>
    </link>

    <link name="link_fixed_7_hinge">
      <visual name="visual_cylinder_fixed_7_hinge">
        <origin xyz="0 0 0" rpy="0 0 0"/>
        <geometry>
          <cylinder radius="0.112" length="0.989"/>
        </geometry>
        <material name="gray"/>
      </visual>
    </link>

    <link name="link_fixed_8_handle_shaft">
      <visual name="visual_cylinder_fixed_8_handle_shaft">
        <origin xyz="0 0 0" rpy="0 0 0"/>
        <geometry>
          <cylinder radius="0.0995" length="0.499"/>
        </geometry>
        <material name="red"/>
      </visual>
      <collision name="collision_cylinder_fixed_8_handle_shaft">
        <origin xyz="0 0 0" rpy="0 0 0"/>
        <geometry>
          <cylinder radius="0.0995" length="0.499"/>
        </geometry>
      </collision>
    </link>

    <link name="link_fixed_9_handle_knob">
      <visual name="visual_box_fixed_9_handle_knob">
        <origin xyz="0 0 0" rpy="0 0 0"/>
        <geometry>
          <box size="0.049 0.049 0.199"/>
        </geometry>
        <material name="yellow"/>
      </visual>
      <collision name="collision_box_fixed_9_handle_knob">
        <origin xyz="0 0 0" rpy="0 0 0"/>
        <geometry>
          <box size="0.049 0.049 0.199"/>
        </geometry>
      </collision>
    </link>

    <joint name="goal" type="fixed">
      <origin xyz="2.0 0.5 0.45" rpy="0 0 0"/>
      <parent link="base_link"/>
      <child link="goal"/>
      <limit effort="0" velocity="0"/>
    </joint>

    <joint name="link_0_joint_0" type="prismatic">
      <origin xyz="1.0 0.5 0.45" rpy="0 0 0"/>
      <parent link="base_link"/>
      <child link="link_0_joint_0"/>
      <axis xyz="1.0 0 0"/>
      <limit lower="0" upper="1.0" effort="0" velocity="0"/>
    </joint>

    <joint name="link_1_joint_0" type="prismatic">
      <origin xyz="2.5 0 0.45" rpy="0 0 -1.5708"/>
      <parent link="base_link"/>
      <child link="link_1_joint_0"/>
      <axis xyz="1.0 0 0"/>
      <limit lower="0" upper="1.0" effort="0" velocity="0"/>
    </joint>

    <joint name="link_2_joint_0" type="revolute">
      <origin xyz="3.5 -1.5 0.45" rpy="0 0 0"/>
      <parent link="base_link"/>
      <child link="link_2_joint_0"/>
      <axis xyz="0 0 1.0"/>
      <limit lower="0" upper="1.5708" effort="0" velocity="0"/>
    </joint>

    <joint name="link_3_joint_0" type="revolute">
      <origin xyz="3.5 -3.5 0.45" rpy="0 0 1.5708"/>
      <parent link="base_link"/>
      <child link="link_3_joint_0"/>
      <axis xyz="0 0 1.0"/>
      <limit lower="-1.5708" upper="0" effort="0" velocity="0"/>
    </joint>

    <joint name="link_4_joint_0" type="prismatic">
      <origin xyz="2.0 -2.5 0.45" rpy="0 0 3.14159"/>
      <parent link="base_link"/>
      <child link="link_4_joint_0"/>
      <axis xyz="1.0 0 0"/>
      <limit lower="0" upper="1.0" effort="0" velocity="0"/>
    </joint>

    <joint name="link_fixed_11_hinge" type="fixed">
      <origin xyz="0 0 0" rpy="0 0 0"/>
      <parent link="link_3_joint_0"/>
      <child link="link_fixed_11_hinge"/>
    </joint>

    <joint name="link_fixed_12_handle_shaft" type="fixed">
      <origin xyz="1.0875 0 0.7" rpy="0 0 0"/>
      <parent link="link_3_joint_0"/>
      <child link="link_fixed_12_handle_shaft"/>
    </joint>

    <joint name="link_fixed_13_handle_knob" type="fixed">
      <origin xyz="0 0 0.35" rpy="0 0 0"/>
      <parent link="link_fixed_12_handle_shaft"/>
      <child link="link_fixed_13_handle_knob"/>
    </joint>

    <joint name="link_fixed_15_handle_shaft" type="fixed">
      <origin xyz="0 0 0.7" rpy="0 0 0"/>
      <parent link="link_4_joint_0"/>
      <child link="link_fixed_15_handle_shaft"/>
    </joint>

    <joint name="link_fixed_16_handle_knob" type="fixed">
      <origin xyz="0 0 0.35" rpy="0 0 0"/>
      <parent link="link_fixed_15_handle_shaft"/>
      <child link="link_fixed_16_handle_knob"/>
    </joint>

    <joint name="link_fixed_1_handle_shaft" type="fixed">
      <origin xyz="0 0 0.7" rpy="0 0 0"/>
      <parent link="link_0_joint_0"/>
      <child link="link_fixed_1_handle_shaft"/>
    </joint>

    <joint name="link_fixed_1_handle_shaft.001" type="fixed">
      <origin xyz="0 0 0.6993" rpy="0 0 0"/>
      <parent link="goal"/>
      <child link="link_fixed_1_handle_shaft.001"/>
    </joint>

    <joint name="link_fixed_2_handle_knob" type="fixed">
      <origin xyz="0 0 0.35" rpy="0 0 0"/>
      <parent link="link_fixed_1_handle_shaft"/>
      <child link="link_fixed_2_handle_knob"/>
    </joint>

    <joint name="link_fixed_2_handle_knob.001" type="fixed">
      <origin xyz="0 0 0.34965" rpy="0 0 0"/>
      <parent link="link_fixed_1_handle_shaft.001"/>
      <child link="link_fixed_2_handle_knob.001"/>
    </joint>

    <joint name="link_fixed_4_handle_shaft" type="fixed">
      <origin xyz="0 0 0.7" rpy="0 0 0"/>
      <parent link="link_1_joint_0"/>
      <child link="link_fixed_4_handle_shaft"/>
    </joint>

    <joint name="link_fixed_5_handle_knob" type="fixed">
      <origin xyz="0 0 0.35" rpy="0 0 0"/>
      <parent link="link_fixed_4_handle_shaft"/>
      <child link="link_fixed_5_handle_knob"/>
    </joint>

    <joint name="link_fixed_7_hinge" type="fixed">
      <origin xyz="0 0 0" rpy="0 0 0"/>
      <parent link="link_2_joint_0"/>
      <child link="link_fixed_7_hinge"/>
    </joint>

    <joint name="link_fixed_8_handle_shaft" type="fixed">
      <origin xyz="1.0875 0 0.7" rpy="0 0 0"/>
      <parent link="link_2_joint_0"/>
      <child link="link_fixed_8_handle_shaft"/>
    </joint>

    <joint name="link_fixed_9_handle_knob" type="fixed">
      <origin xyz="0 0 0.35" rpy="0 0 0"/>
      <parent link="link_fixed_8_handle_shaft"/>
      <child link="link_fixed_9_handle_knob"/>
    </joint>

    <material name="gray">
      <color rgba="0.5 0.5 0.5 1.0"/>
    </material>

    <material name="green">
      <color rgba="0 1.0 0 1.0"/>
    </material>

    <material name="green_translucent">
      <color rgba="0 1.0 0 0.25"/>
    </material>

    <material name="red">
      <color rgba="1.0 0 0 1.0"/>
    </material>

    <material name="yellow">
      <color rgba="1.0 1.0 0 1.0"/>
    </material>

  </robot>
